2023-09-02 18:31:37,885 INFO autoreload Watching for file changes with StatReloader
2023-09-02 18:33:39,569 INFO autoreload Watching for file changes with StatReloader
2023-09-02 18:37:15,284 ERROR log Internal Server Error: /news/create/
Traceback (most recent call last):
  File "C:\Users\Trewor\PycharmProjects\new_Project_Django\venv\lib\site-packages\redis\connection.py", line 707, in connect
    sock = self.retry.call_with_retry(
  File "C:\Users\Trewor\PycharmProjects\new_Project_Django\venv\lib\site-packages\redis\retry.py", line 46, in call_with_retry
    return do()
  File "C:\Users\Trewor\PycharmProjects\new_Project_Django\venv\lib\site-packages\redis\connection.py", line 708, in <lambda>
    lambda: self._connect(), lambda error: self.disconnect(error)
  File "C:\Users\Trewor\PycharmProjects\new_Project_Django\venv\lib\site-packages\redis\connection.py", line 974, in _connect
    for res in socket.getaddrinfo(
  File "C:\python-3.10.8-amd64\lib\socket.py", line 955, in getaddrinfo
    for res in _socket.getaddrinfo(host, port, family, type, proto, flags):
socket.gaierror: [Errno 11001] getaddrinfo failed

During handling of the above exception, another exception occurred:

Traceback (most recent call last):
  File "C:\Users\Trewor\PycharmProjects\new_Project_Django\venv\lib\site-packages\celery\backends\redis.py", line 127, in reconnect_on_error
    yield
  File "C:\Users\Trewor\PycharmProjects\new_Project_Django\venv\lib\site-packages\celery\backends\redis.py", line 177, in _consume_from
    self._pubsub.subscribe(key)
  File "C:\Users\Trewor\PycharmProjects\new_Project_Django\venv\lib\site-packages\redis\client.py", line 1634, in subscribe
    ret_val = self.execute_command("SUBSCRIBE", *new_channels.keys())
  File "C:\Users\Trewor\PycharmProjects\new_Project_Django\venv\lib\site-packages\redis\client.py", line 1469, in execute_command
    self.connection = self.connection_pool.get_connection(
  File "C:\Users\Trewor\PycharmProjects\new_Project_Django\venv\lib\site-packages\redis\connection.py", line 1461, in get_connection
    connection.connect()
  File "C:\Users\Trewor\PycharmProjects\new_Project_Django\venv\lib\site-packages\redis\connection.py", line 713, in connect
    raise ConnectionError(self._error_message(e))
redis.exceptions.ConnectionError: Error 11001 connecting to redis-14227.c1.asia-northeast1-1.gce.cloud.redislabs.com:14227. getaddrinfo failed.

During handling of the above exception, another exception occurred:

Traceback (most recent call last):
  File "C:\Users\Trewor\PycharmProjects\new_Project_Django\venv\lib\site-packages\redis\connection.py", line 707, in connect
    sock = self.retry.call_with_retry(
  File "C:\Users\Trewor\PycharmProjects\new_Project_Django\venv\lib\site-packages\redis\retry.py", line 46, in call_with_retry
    return do()
  File "C:\Users\Trewor\PycharmProjects\new_Project_Django\venv\lib\site-packages\redis\connection.py", line 708, in <lambda>
    lambda: self._connect(), lambda error: self.disconnect(error)
  File "C:\Users\Trewor\PycharmProjects\new_Project_Django\venv\lib\site-packages\redis\connection.py", line 974, in _connect
    for res in socket.getaddrinfo(
  File "C:\python-3.10.8-amd64\lib\socket.py", line 955, in getaddrinfo
    for res in _socket.getaddrinfo(host, port, family, type, proto, flags):
socket.gaierror: [Errno 11001] getaddrinfo failed

During handling of the above exception, another exception occurred:

Traceback (most recent call last):
  File "C:\Users\Trewor\PycharmProjects\new_Project_Django\venv\lib\site-packages\kombu\connection.py", line 472, in _reraise_as_library_errors
    yield
  File "C:\Users\Trewor\PycharmProjects\new_Project_Django\venv\lib\site-packages\celery\app\base.py", line 797, in send_task
    self.backend.on_task_call(P, task_id)
  File "C:\Users\Trewor\PycharmProjects\new_Project_Django\venv\lib\site-packages\celery\backends\redis.py", line 373, in on_task_call
    self.result_consumer.consume_from(task_id)
  File "C:\Users\Trewor\PycharmProjects\new_Project_Django\venv\lib\site-packages\celery\backends\redis.py", line 169, in consume_from
    return self.start(task_id)
  File "C:\Users\Trewor\PycharmProjects\new_Project_Django\venv\lib\site-packages\celery\backends\redis.py", line 147, in start
    self._consume_from(initial_task_id)
  File "C:\Users\Trewor\PycharmProjects\new_Project_Django\venv\lib\site-packages\celery\backends\redis.py", line 176, in _consume_from
    with self.reconnect_on_error():
  File "C:\python-3.10.8-amd64\lib\contextlib.py", line 153, in __exit__
    self.gen.throw(typ, value, traceback)
  File "C:\Users\Trewor\PycharmProjects\new_Project_Django\venv\lib\site-packages\celery\backends\redis.py", line 130, in reconnect_on_error
    self._ensure(self._reconnect_pubsub, ())
  File "C:\Users\Trewor\PycharmProjects\new_Project_Django\venv\lib\site-packages\celery\backends\redis.py", line 384, in ensure
    return retry_over_time(
  File "C:\Users\Trewor\PycharmProjects\new_Project_Django\venv\lib\site-packages\kombu\utils\functional.py", line 318, in retry_over_time
    return fun(*args, **kwargs)
  File "C:\Users\Trewor\PycharmProjects\new_Project_Django\venv\lib\site-packages\celery\backends\redis.py", line 106, in _reconnect_pubsub
    metas = self.backend.client.mget(self.subscribed_to)
  File "C:\Users\Trewor\PycharmProjects\new_Project_Django\venv\lib\site-packages\redis\commands\core.py", line 2002, in mget
    return self.execute_command("MGET", *args, **options)
  File "C:\Users\Trewor\PycharmProjects\new_Project_Django\venv\lib\site-packages\redis\client.py", line 1266, in execute_command
    conn = self.connection or pool.get_connection(command_name, **options)
  File "C:\Users\Trewor\PycharmProjects\new_Project_Django\venv\lib\site-packages\redis\connection.py", line 1461, in get_connection
    connection.connect()
  File "C:\Users\Trewor\PycharmProjects\new_Project_Django\venv\lib\site-packages\redis\connection.py", line 713, in connect
    raise ConnectionError(self._error_message(e))
redis.exceptions.ConnectionError: Error 11001 connecting to redis-14227.c1.asia-northeast1-1.gce.cloud.redislabs.com:14227. getaddrinfo failed.

The above exception was the direct cause of the following exception:

Traceback (most recent call last):
  File "C:\Users\Trewor\PycharmProjects\new_Project_Django\venv\lib\site-packages\django\core\handlers\exception.py", line 55, in inner
    response = get_response(request)
  File "C:\Users\Trewor\PycharmProjects\new_Project_Django\venv\lib\site-packages\django\core\handlers\base.py", line 197, in _get_response
    response = wrapped_callback(request, *callback_args, **callback_kwargs)
  File "C:\Users\Trewor\PycharmProjects\new_Project_Django\venv\lib\site-packages\django\views\generic\base.py", line 104, in view
    return self.dispatch(request, *args, **kwargs)
  File "C:\Users\Trewor\PycharmProjects\new_Project_Django\venv\lib\site-packages\django\contrib\auth\mixins.py", line 109, in dispatch
    return super().dispatch(request, *args, **kwargs)
  File "C:\Users\Trewor\PycharmProjects\new_Project_Django\venv\lib\site-packages\django\views\generic\base.py", line 143, in dispatch
    return handler(request, *args, **kwargs)
  File "C:\Users\Trewor\PycharmProjects\new_Project_Django\venv\lib\site-packages\django\views\generic\edit.py", line 184, in post
    return super().post(request, *args, **kwargs)
  File "C:\Users\Trewor\PycharmProjects\new_Project_Django\venv\lib\site-packages\django\views\generic\edit.py", line 153, in post
    return self.form_valid(form)
  File "C:\Users\Trewor\PycharmProjects\new_Project_Django\NewsPaper\news\views.py", line 68, in form_valid
    return super().form_valid(form)
  File "C:\Users\Trewor\PycharmProjects\new_Project_Django\venv\lib\site-packages\django\views\generic\edit.py", line 135, in form_valid
    self.object = form.save()
  File "C:\Users\Trewor\PycharmProjects\new_Project_Django\venv\lib\site-packages\django\forms\models.py", line 542, in save
    self.instance.save()
  File "C:\Users\Trewor\PycharmProjects\new_Project_Django\NewsPaper\news\models.py", line 60, in save
    super().save(*args, *kwargs)
  File "C:\Users\Trewor\PycharmProjects\new_Project_Django\venv\lib\site-packages\django\db\models\base.py", line 814, in save
    self.save_base(
  File "C:\Users\Trewor\PycharmProjects\new_Project_Django\venv\lib\site-packages\django\db\models\base.py", line 892, in save_base
    post_save.send(
  File "C:\Users\Trewor\PycharmProjects\new_Project_Django\venv\lib\site-packages\django\dispatch\dispatcher.py", line 176, in send
    return [
  File "C:\Users\Trewor\PycharmProjects\new_Project_Django\venv\lib\site-packages\django\dispatch\dispatcher.py", line 177, in <listcomp>
    (receiver, receiver(signal=self, sender=sender, **named))
  File "C:\Users\Trewor\PycharmProjects\new_Project_Django\NewsPaper\news\signals.py", line 39, in post_send
    new_post_send.delay(instance.id)
  File "C:\Users\Trewor\PycharmProjects\new_Project_Django\venv\lib\site-packages\celery\app\task.py", line 444, in delay
    return self.apply_async(args, kwargs)
  File "C:\Users\Trewor\PycharmProjects\new_Project_Django\venv\lib\site-packages\celery\app\task.py", line 594, in apply_async
    return app.send_task(
  File "C:\Users\Trewor\PycharmProjects\new_Project_Django\venv\lib\site-packages\celery\app\base.py", line 795, in send_task
    with P.connection._reraise_as_library_errors():
  File "C:\python-3.10.8-amd64\lib\contextlib.py", line 153, in __exit__
    self.gen.throw(typ, value, traceback)
  File "C:\Users\Trewor\PycharmProjects\new_Project_Django\venv\lib\site-packages\kombu\connection.py", line 476, in _reraise_as_library_errors
    raise ConnectionError(str(exc)) from exc
kombu.exceptions.OperationalError: Error 11001 connecting to redis-14227.c1.asia-northeast1-1.gce.cloud.redislabs.com:14227. getaddrinfo failed.
2023-09-02 18:37:18,329 ERROR log Internal Server Error: /news/create/
Traceback (most recent call last):
  File "C:\Users\Trewor\PycharmProjects\new_Project_Django\venv\lib\site-packages\redis\connection.py", line 707, in connect
    sock = self.retry.call_with_retry(
  File "C:\Users\Trewor\PycharmProjects\new_Project_Django\venv\lib\site-packages\redis\retry.py", line 46, in call_with_retry
    return do()
  File "C:\Users\Trewor\PycharmProjects\new_Project_Django\venv\lib\site-packages\redis\connection.py", line 708, in <lambda>
    lambda: self._connect(), lambda error: self.disconnect(error)
  File "C:\Users\Trewor\PycharmProjects\new_Project_Django\venv\lib\site-packages\redis\connection.py", line 974, in _connect
    for res in socket.getaddrinfo(
  File "C:\python-3.10.8-amd64\lib\socket.py", line 955, in getaddrinfo
    for res in _socket.getaddrinfo(host, port, family, type, proto, flags):
socket.gaierror: [Errno 11001] getaddrinfo failed

During handling of the above exception, another exception occurred:

Traceback (most recent call last):
  File "C:\Users\Trewor\PycharmProjects\new_Project_Django\venv\lib\site-packages\celery\backends\redis.py", line 127, in reconnect_on_error
    yield
  File "C:\Users\Trewor\PycharmProjects\new_Project_Django\venv\lib\site-packages\celery\backends\redis.py", line 177, in _consume_from
    self._pubsub.subscribe(key)
  File "C:\Users\Trewor\PycharmProjects\new_Project_Django\venv\lib\site-packages\redis\client.py", line 1634, in subscribe
    ret_val = self.execute_command("SUBSCRIBE", *new_channels.keys())
  File "C:\Users\Trewor\PycharmProjects\new_Project_Django\venv\lib\site-packages\redis\client.py", line 1469, in execute_command
    self.connection = self.connection_pool.get_connection(
  File "C:\Users\Trewor\PycharmProjects\new_Project_Django\venv\lib\site-packages\redis\connection.py", line 1461, in get_connection
    connection.connect()
  File "C:\Users\Trewor\PycharmProjects\new_Project_Django\venv\lib\site-packages\redis\connection.py", line 713, in connect
    raise ConnectionError(self._error_message(e))
redis.exceptions.ConnectionError: Error 11001 connecting to redis-14227.c1.asia-northeast1-1.gce.cloud.redislabs.com:14227. getaddrinfo failed.

During handling of the above exception, another exception occurred:

Traceback (most recent call last):
  File "C:\Users\Trewor\PycharmProjects\new_Project_Django\venv\lib\site-packages\redis\connection.py", line 707, in connect
    sock = self.retry.call_with_retry(
  File "C:\Users\Trewor\PycharmProjects\new_Project_Django\venv\lib\site-packages\redis\retry.py", line 46, in call_with_retry
    return do()
  File "C:\Users\Trewor\PycharmProjects\new_Project_Django\venv\lib\site-packages\redis\connection.py", line 708, in <lambda>
    lambda: self._connect(), lambda error: self.disconnect(error)
  File "C:\Users\Trewor\PycharmProjects\new_Project_Django\venv\lib\site-packages\redis\connection.py", line 974, in _connect
    for res in socket.getaddrinfo(
  File "C:\python-3.10.8-amd64\lib\socket.py", line 955, in getaddrinfo
    for res in _socket.getaddrinfo(host, port, family, type, proto, flags):
socket.gaierror: [Errno 11001] getaddrinfo failed

During handling of the above exception, another exception occurred:

Traceback (most recent call last):
  File "C:\Users\Trewor\PycharmProjects\new_Project_Django\venv\lib\site-packages\kombu\connection.py", line 472, in _reraise_as_library_errors
    yield
  File "C:\Users\Trewor\PycharmProjects\new_Project_Django\venv\lib\site-packages\celery\app\base.py", line 797, in send_task
    self.backend.on_task_call(P, task_id)
  File "C:\Users\Trewor\PycharmProjects\new_Project_Django\venv\lib\site-packages\celery\backends\redis.py", line 373, in on_task_call
    self.result_consumer.consume_from(task_id)
  File "C:\Users\Trewor\PycharmProjects\new_Project_Django\venv\lib\site-packages\celery\backends\redis.py", line 169, in consume_from
    return self.start(task_id)
  File "C:\Users\Trewor\PycharmProjects\new_Project_Django\venv\lib\site-packages\celery\backends\redis.py", line 147, in start
    self._consume_from(initial_task_id)
  File "C:\Users\Trewor\PycharmProjects\new_Project_Django\venv\lib\site-packages\celery\backends\redis.py", line 176, in _consume_from
    with self.reconnect_on_error():
  File "C:\python-3.10.8-amd64\lib\contextlib.py", line 153, in __exit__
    self.gen.throw(typ, value, traceback)
  File "C:\Users\Trewor\PycharmProjects\new_Project_Django\venv\lib\site-packages\celery\backends\redis.py", line 130, in reconnect_on_error
    self._ensure(self._reconnect_pubsub, ())
  File "C:\Users\Trewor\PycharmProjects\new_Project_Django\venv\lib\site-packages\celery\backends\redis.py", line 384, in ensure
    return retry_over_time(
  File "C:\Users\Trewor\PycharmProjects\new_Project_Django\venv\lib\site-packages\kombu\utils\functional.py", line 318, in retry_over_time
    return fun(*args, **kwargs)
  File "C:\Users\Trewor\PycharmProjects\new_Project_Django\venv\lib\site-packages\celery\backends\redis.py", line 106, in _reconnect_pubsub
    metas = self.backend.client.mget(self.subscribed_to)
  File "C:\Users\Trewor\PycharmProjects\new_Project_Django\venv\lib\site-packages\redis\commands\core.py", line 2002, in mget
    return self.execute_command("MGET", *args, **options)
  File "C:\Users\Trewor\PycharmProjects\new_Project_Django\venv\lib\site-packages\redis\client.py", line 1266, in execute_command
    conn = self.connection or pool.get_connection(command_name, **options)
  File "C:\Users\Trewor\PycharmProjects\new_Project_Django\venv\lib\site-packages\redis\connection.py", line 1461, in get_connection
    connection.connect()
  File "C:\Users\Trewor\PycharmProjects\new_Project_Django\venv\lib\site-packages\redis\connection.py", line 713, in connect
    raise ConnectionError(self._error_message(e))
redis.exceptions.ConnectionError: Error 11001 connecting to redis-14227.c1.asia-northeast1-1.gce.cloud.redislabs.com:14227. getaddrinfo failed.

The above exception was the direct cause of the following exception:

Traceback (most recent call last):
  File "C:\Users\Trewor\PycharmProjects\new_Project_Django\venv\lib\site-packages\django\core\handlers\exception.py", line 55, in inner
    response = get_response(request)
  File "C:\Users\Trewor\PycharmProjects\new_Project_Django\venv\lib\site-packages\django\core\handlers\base.py", line 197, in _get_response
    response = wrapped_callback(request, *callback_args, **callback_kwargs)
  File "C:\Users\Trewor\PycharmProjects\new_Project_Django\venv\lib\site-packages\django\views\generic\base.py", line 104, in view
    return self.dispatch(request, *args, **kwargs)
  File "C:\Users\Trewor\PycharmProjects\new_Project_Django\venv\lib\site-packages\django\contrib\auth\mixins.py", line 109, in dispatch
    return super().dispatch(request, *args, **kwargs)
  File "C:\Users\Trewor\PycharmProjects\new_Project_Django\venv\lib\site-packages\django\views\generic\base.py", line 143, in dispatch
    return handler(request, *args, **kwargs)
  File "C:\Users\Trewor\PycharmProjects\new_Project_Django\venv\lib\site-packages\django\views\generic\edit.py", line 184, in post
    return super().post(request, *args, **kwargs)
  File "C:\Users\Trewor\PycharmProjects\new_Project_Django\venv\lib\site-packages\django\views\generic\edit.py", line 153, in post
    return self.form_valid(form)
  File "C:\Users\Trewor\PycharmProjects\new_Project_Django\NewsPaper\news\views.py", line 68, in form_valid
    return super().form_valid(form)
  File "C:\Users\Trewor\PycharmProjects\new_Project_Django\venv\lib\site-packages\django\views\generic\edit.py", line 135, in form_valid
    self.object = form.save()
  File "C:\Users\Trewor\PycharmProjects\new_Project_Django\venv\lib\site-packages\django\forms\models.py", line 542, in save
    self.instance.save()
  File "C:\Users\Trewor\PycharmProjects\new_Project_Django\NewsPaper\news\models.py", line 60, in save
    super().save(*args, *kwargs)
  File "C:\Users\Trewor\PycharmProjects\new_Project_Django\venv\lib\site-packages\django\db\models\base.py", line 814, in save
    self.save_base(
  File "C:\Users\Trewor\PycharmProjects\new_Project_Django\venv\lib\site-packages\django\db\models\base.py", line 892, in save_base
    post_save.send(
  File "C:\Users\Trewor\PycharmProjects\new_Project_Django\venv\lib\site-packages\django\dispatch\dispatcher.py", line 176, in send
    return [
  File "C:\Users\Trewor\PycharmProjects\new_Project_Django\venv\lib\site-packages\django\dispatch\dispatcher.py", line 177, in <listcomp>
    (receiver, receiver(signal=self, sender=sender, **named))
  File "C:\Users\Trewor\PycharmProjects\new_Project_Django\NewsPaper\news\signals.py", line 39, in post_send
    new_post_send.delay(instance.id)
  File "C:\Users\Trewor\PycharmProjects\new_Project_Django\venv\lib\site-packages\celery\app\task.py", line 444, in delay
    return self.apply_async(args, kwargs)
  File "C:\Users\Trewor\PycharmProjects\new_Project_Django\venv\lib\site-packages\celery\app\task.py", line 594, in apply_async
    return app.send_task(
  File "C:\Users\Trewor\PycharmProjects\new_Project_Django\venv\lib\site-packages\celery\app\base.py", line 795, in send_task
    with P.connection._reraise_as_library_errors():
  File "C:\python-3.10.8-amd64\lib\contextlib.py", line 153, in __exit__
    self.gen.throw(typ, value, traceback)
  File "C:\Users\Trewor\PycharmProjects\new_Project_Django\venv\lib\site-packages\kombu\connection.py", line 476, in _reraise_as_library_errors
    raise ConnectionError(str(exc)) from exc
kombu.exceptions.OperationalError: Error 11001 connecting to redis-14227.c1.asia-northeast1-1.gce.cloud.redislabs.com:14227. getaddrinfo failed.
2023-09-02 18:38:13,152 ERROR log Internal Server Error: /news/create/
Traceback (most recent call last):
  File "C:\Users\Trewor\PycharmProjects\new_Project_Django\venv\lib\site-packages\redis\connection.py", line 707, in connect
    sock = self.retry.call_with_retry(
  File "C:\Users\Trewor\PycharmProjects\new_Project_Django\venv\lib\site-packages\redis\retry.py", line 46, in call_with_retry
    return do()
  File "C:\Users\Trewor\PycharmProjects\new_Project_Django\venv\lib\site-packages\redis\connection.py", line 708, in <lambda>
    lambda: self._connect(), lambda error: self.disconnect(error)
  File "C:\Users\Trewor\PycharmProjects\new_Project_Django\venv\lib\site-packages\redis\connection.py", line 974, in _connect
    for res in socket.getaddrinfo(
  File "C:\python-3.10.8-amd64\lib\socket.py", line 955, in getaddrinfo
    for res in _socket.getaddrinfo(host, port, family, type, proto, flags):
socket.gaierror: [Errno 11001] getaddrinfo failed

During handling of the above exception, another exception occurred:

Traceback (most recent call last):
  File "C:\Users\Trewor\PycharmProjects\new_Project_Django\venv\lib\site-packages\celery\backends\redis.py", line 127, in reconnect_on_error
    yield
  File "C:\Users\Trewor\PycharmProjects\new_Project_Django\venv\lib\site-packages\celery\backends\redis.py", line 177, in _consume_from
    self._pubsub.subscribe(key)
  File "C:\Users\Trewor\PycharmProjects\new_Project_Django\venv\lib\site-packages\redis\client.py", line 1634, in subscribe
    ret_val = self.execute_command("SUBSCRIBE", *new_channels.keys())
  File "C:\Users\Trewor\PycharmProjects\new_Project_Django\venv\lib\site-packages\redis\client.py", line 1469, in execute_command
    self.connection = self.connection_pool.get_connection(
  File "C:\Users\Trewor\PycharmProjects\new_Project_Django\venv\lib\site-packages\redis\connection.py", line 1461, in get_connection
    connection.connect()
  File "C:\Users\Trewor\PycharmProjects\new_Project_Django\venv\lib\site-packages\redis\connection.py", line 713, in connect
    raise ConnectionError(self._error_message(e))
redis.exceptions.ConnectionError: Error 11001 connecting to redis-14227.c1.asia-northeast1-1.gce.cloud.redislabs.com:14227. getaddrinfo failed.

During handling of the above exception, another exception occurred:

Traceback (most recent call last):
  File "C:\Users\Trewor\PycharmProjects\new_Project_Django\venv\lib\site-packages\redis\connection.py", line 707, in connect
    sock = self.retry.call_with_retry(
  File "C:\Users\Trewor\PycharmProjects\new_Project_Django\venv\lib\site-packages\redis\retry.py", line 46, in call_with_retry
    return do()
  File "C:\Users\Trewor\PycharmProjects\new_Project_Django\venv\lib\site-packages\redis\connection.py", line 708, in <lambda>
    lambda: self._connect(), lambda error: self.disconnect(error)
  File "C:\Users\Trewor\PycharmProjects\new_Project_Django\venv\lib\site-packages\redis\connection.py", line 974, in _connect
    for res in socket.getaddrinfo(
  File "C:\python-3.10.8-amd64\lib\socket.py", line 955, in getaddrinfo
    for res in _socket.getaddrinfo(host, port, family, type, proto, flags):
socket.gaierror: [Errno 11001] getaddrinfo failed

During handling of the above exception, another exception occurred:

Traceback (most recent call last):
  File "C:\Users\Trewor\PycharmProjects\new_Project_Django\venv\lib\site-packages\kombu\connection.py", line 472, in _reraise_as_library_errors
    yield
  File "C:\Users\Trewor\PycharmProjects\new_Project_Django\venv\lib\site-packages\celery\app\base.py", line 797, in send_task
    self.backend.on_task_call(P, task_id)
  File "C:\Users\Trewor\PycharmProjects\new_Project_Django\venv\lib\site-packages\celery\backends\redis.py", line 373, in on_task_call
    self.result_consumer.consume_from(task_id)
  File "C:\Users\Trewor\PycharmProjects\new_Project_Django\venv\lib\site-packages\celery\backends\redis.py", line 169, in consume_from
    return self.start(task_id)
  File "C:\Users\Trewor\PycharmProjects\new_Project_Django\venv\lib\site-packages\celery\backends\redis.py", line 147, in start
    self._consume_from(initial_task_id)
  File "C:\Users\Trewor\PycharmProjects\new_Project_Django\venv\lib\site-packages\celery\backends\redis.py", line 176, in _consume_from
    with self.reconnect_on_error():
  File "C:\python-3.10.8-amd64\lib\contextlib.py", line 153, in __exit__
    self.gen.throw(typ, value, traceback)
  File "C:\Users\Trewor\PycharmProjects\new_Project_Django\venv\lib\site-packages\celery\backends\redis.py", line 130, in reconnect_on_error
    self._ensure(self._reconnect_pubsub, ())
  File "C:\Users\Trewor\PycharmProjects\new_Project_Django\venv\lib\site-packages\celery\backends\redis.py", line 384, in ensure
    return retry_over_time(
  File "C:\Users\Trewor\PycharmProjects\new_Project_Django\venv\lib\site-packages\kombu\utils\functional.py", line 318, in retry_over_time
    return fun(*args, **kwargs)
  File "C:\Users\Trewor\PycharmProjects\new_Project_Django\venv\lib\site-packages\celery\backends\redis.py", line 106, in _reconnect_pubsub
    metas = self.backend.client.mget(self.subscribed_to)
  File "C:\Users\Trewor\PycharmProjects\new_Project_Django\venv\lib\site-packages\redis\commands\core.py", line 2002, in mget
    return self.execute_command("MGET", *args, **options)
  File "C:\Users\Trewor\PycharmProjects\new_Project_Django\venv\lib\site-packages\redis\client.py", line 1266, in execute_command
    conn = self.connection or pool.get_connection(command_name, **options)
  File "C:\Users\Trewor\PycharmProjects\new_Project_Django\venv\lib\site-packages\redis\connection.py", line 1461, in get_connection
    connection.connect()
  File "C:\Users\Trewor\PycharmProjects\new_Project_Django\venv\lib\site-packages\redis\connection.py", line 713, in connect
    raise ConnectionError(self._error_message(e))
redis.exceptions.ConnectionError: Error 11001 connecting to redis-14227.c1.asia-northeast1-1.gce.cloud.redislabs.com:14227. getaddrinfo failed.

The above exception was the direct cause of the following exception:

Traceback (most recent call last):
  File "C:\Users\Trewor\PycharmProjects\new_Project_Django\venv\lib\site-packages\django\core\handlers\exception.py", line 55, in inner
    response = get_response(request)
  File "C:\Users\Trewor\PycharmProjects\new_Project_Django\venv\lib\site-packages\django\core\handlers\base.py", line 197, in _get_response
    response = wrapped_callback(request, *callback_args, **callback_kwargs)
  File "C:\Users\Trewor\PycharmProjects\new_Project_Django\venv\lib\site-packages\django\views\generic\base.py", line 104, in view
    return self.dispatch(request, *args, **kwargs)
  File "C:\Users\Trewor\PycharmProjects\new_Project_Django\venv\lib\site-packages\django\contrib\auth\mixins.py", line 109, in dispatch
    return super().dispatch(request, *args, **kwargs)
  File "C:\Users\Trewor\PycharmProjects\new_Project_Django\venv\lib\site-packages\django\views\generic\base.py", line 143, in dispatch
    return handler(request, *args, **kwargs)
  File "C:\Users\Trewor\PycharmProjects\new_Project_Django\venv\lib\site-packages\django\views\generic\edit.py", line 184, in post
    return super().post(request, *args, **kwargs)
  File "C:\Users\Trewor\PycharmProjects\new_Project_Django\venv\lib\site-packages\django\views\generic\edit.py", line 153, in post
    return self.form_valid(form)
  File "C:\Users\Trewor\PycharmProjects\new_Project_Django\NewsPaper\news\views.py", line 68, in form_valid
    return super().form_valid(form)
  File "C:\Users\Trewor\PycharmProjects\new_Project_Django\venv\lib\site-packages\django\views\generic\edit.py", line 135, in form_valid
    self.object = form.save()
  File "C:\Users\Trewor\PycharmProjects\new_Project_Django\venv\lib\site-packages\django\forms\models.py", line 542, in save
    self.instance.save()
  File "C:\Users\Trewor\PycharmProjects\new_Project_Django\NewsPaper\news\models.py", line 60, in save
    super().save(*args, *kwargs)
  File "C:\Users\Trewor\PycharmProjects\new_Project_Django\venv\lib\site-packages\django\db\models\base.py", line 814, in save
    self.save_base(
  File "C:\Users\Trewor\PycharmProjects\new_Project_Django\venv\lib\site-packages\django\db\models\base.py", line 892, in save_base
    post_save.send(
  File "C:\Users\Trewor\PycharmProjects\new_Project_Django\venv\lib\site-packages\django\dispatch\dispatcher.py", line 176, in send
    return [
  File "C:\Users\Trewor\PycharmProjects\new_Project_Django\venv\lib\site-packages\django\dispatch\dispatcher.py", line 177, in <listcomp>
    (receiver, receiver(signal=self, sender=sender, **named))
  File "C:\Users\Trewor\PycharmProjects\new_Project_Django\NewsPaper\news\signals.py", line 39, in post_send
    new_post_send.delay(instance.id)
  File "C:\Users\Trewor\PycharmProjects\new_Project_Django\venv\lib\site-packages\celery\app\task.py", line 444, in delay
    return self.apply_async(args, kwargs)
  File "C:\Users\Trewor\PycharmProjects\new_Project_Django\venv\lib\site-packages\celery\app\task.py", line 594, in apply_async
    return app.send_task(
  File "C:\Users\Trewor\PycharmProjects\new_Project_Django\venv\lib\site-packages\celery\app\base.py", line 795, in send_task
    with P.connection._reraise_as_library_errors():
  File "C:\python-3.10.8-amd64\lib\contextlib.py", line 153, in __exit__
    self.gen.throw(typ, value, traceback)
  File "C:\Users\Trewor\PycharmProjects\new_Project_Django\venv\lib\site-packages\kombu\connection.py", line 476, in _reraise_as_library_errors
    raise ConnectionError(str(exc)) from exc
kombu.exceptions.OperationalError: Error 11001 connecting to redis-14227.c1.asia-northeast1-1.gce.cloud.redislabs.com:14227. getaddrinfo failed.
2023-09-02 18:39:55,345 INFO autoreload C:\Users\Trewor\PycharmProjects\new_Project_Django\NewsPaper\NewsPaper\settings.py changed, reloading.
2023-09-02 18:39:56,518 INFO autoreload Watching for file changes with StatReloader
2023-09-02 18:43:42,661 INFO autoreload C:\Users\Trewor\PycharmProjects\new_Project_Django\NewsPaper\NewsPaper\settings.py changed, reloading.
